Traceback (most recent call last):
  File "/usr/local/lib/python3.7/threading.py", line 926, in _bootstrap_inner
    self.run()
  File "/usr/local/lib/python3.7/threading.py", line 870, in run
    self._target(*self._args, **self._kwargs)
  File "/usr/local/lib/python3.7/site-packages/django/utils/autoreload.py", line 53, in wrapper
    fn(*args, **kwargs)
  File "/usr/local/lib/python3.7/site-packages/django/core/management/commands/runserver.py", line 121, in inner_run
    self.check_migrations()
  File "/usr/local/lib/python3.7/site-packages/django/core/management/base.py", line 459, in check_migrations
    executor = MigrationExecutor(connections[DEFAULT_DB_ALIAS])
  File "/usr/local/lib/python3.7/site-packages/django/db/migrations/executor.py", line 18, in __init__
    self.loader = MigrationLoader(self.connection)
  File "/usr/local/lib/python3.7/site-packages/django/db/migrations/loader.py", line 53, in __init__
    self.build_graph()
  File "/usr/local/lib/python3.7/site-packages/django/db/migrations/loader.py", line 231, in build_graph
    self.add_external_dependencies(key, migration)
  File "/usr/local/lib/python3.7/site-packages/django/db/migrations/loader.py", line 195, in add_external_dependencies
    parent = self.check_key(parent, key[0])
  File "/usr/local/lib/python3.7/site-packages/django/db/migrations/loader.py", line 177, in check_key
    raise ValueError("Dependency on app with no migrations: %s" % key[0])
ValueError: Dependency on app with no migrations: accounts

select * from accounts_ldapserver;
6|172.21.16.11|389|cn=admin,dc=7otech,dc=com
|sNDXgoeb6x3XnL0cY1Ghhjv4Q2pUbalaJ/ApEwWEE5ngM38YUgw2b2uqndCQigoutLWiwxhIZqm08ikNWOYe27KydUyQiQDCcsEru9NiRJyNjo9r2UDy607aQNQ9bqoIg3XXeSpDo/pLtPfvIDKMk4W9yyOx13dP2X3Tn82UwdI=
|0|openladp||dc=7otech,dc=com|ou=tech||inetOrgPerson|groupOfUniqueNames

python manage.py migrate
Operations to perform:
  Apply all migrations: admin, auth, contenttypes, sessions
Running migrations:
  Applying contenttypes.0001_initial... OK
  Applying admin.0001_initial...Traceback (most recent call last):
  File "/usr/local/lib/python3.7/site-packages/django/db/backends/utils.py", line 84, in _execute
    return self.cursor.execute(sql, params)
  File "/usr/local/lib/python3.7/site-packages/django/db/backends/mysql/base.py", line 73, in execute
    return self.cursor.execute(query, args)
  File "/usr/local/lib/python3.7/site-packages/MySQLdb/cursors.py", line 206, in execute
    res = self._query(query)
  File "/usr/local/lib/python3.7/site-packages/MySQLdb/cursors.py", line 319, in _query
    db.query(q)
  File "/usr/local/lib/python3.7/site-packages/MySQLdb/connections.py", line 254, in query
    _mysql.connection.query(self, query)
MySQLdb._exceptions.OperationalError: (1824, "Failed to open the referenced table 'accounts_user'")

The above exception was the direct cause of the following exception:

Traceback (most recent call last):
  File "manage.py", line 22, in <module>
    main()
  File "manage.py", line 18, in main
    execute_from_command_line(sys.argv)
  File "/usr/local/lib/python3.7/site-packages/django/core/management/__init__.py", line 401, in execute_from_command_line
    utility.execute()
  File "/usr/local/lib/python3.7/site-packages/django/core/management/__init__.py", line 395, in execute
    self.fetch_command(subcommand).run_from_argv(self.argv)
  File "/usr/local/lib/python3.7/site-packages/django/core/management/base.py", line 330, in run_from_argv
    self.execute(*args, **cmd_options)
  File "/usr/local/lib/python3.7/site-packages/django/core/management/base.py", line 371, in execute
    output = self.handle(*args, **options)
  File "/usr/local/lib/python3.7/site-packages/django/core/management/base.py", line 85, in wrapped
    res = handle_func(*args, **kwargs)
  File "/usr/local/lib/python3.7/site-packages/django/core/management/commands/migrate.py", line 245, in handle
    fake_initial=fake_initial,
  File "/usr/local/lib/python3.7/site-packages/django/db/migrations/executor.py", line 117, in migrate
    state = self._migrate_all_forwards(state, plan, full_plan, fake=fake, fake_initial=fake_initial)
  File "/usr/local/lib/python3.7/site-packages/django/db/migrations/executor.py", line 147, in _migrate_all_forwards
    state = self.apply_migration(state, migration, fake=fake, fake_initial=fake_initial)
  File "/usr/local/lib/python3.7/site-packages/django/db/migrations/executor.py", line 229, in apply_migration
    migration_recorded = True
  File "/usr/local/lib/python3.7/site-packages/django/db/backends/base/schema.py", line 115, in __exit__
    self.execute(sql)
  File "/usr/local/lib/python3.7/site-packages/django/db/backends/base/schema.py", line 142, in execute
    cursor.execute(sql, params)
  File "/usr/local/lib/python3.7/site-packages/django/db/backends/utils.py", line 98, in execute
    return super().execute(sql, params)
  File "/usr/local/lib/python3.7/site-packages/django/db/backends/utils.py", line 66, in execute
    return self._execute_with_wrappers(sql, params, many=False, executor=self._execute)
  File "/usr/local/lib/python3.7/site-packages/django/db/backends/utils.py", line 75, in _execute_with_wrappers
    return executor(sql, params, many, context)
  File "/usr/local/lib/python3.7/site-packages/django/db/backends/utils.py", line 84, in _execute
    return self.cursor.execute(sql, params)
  File "/usr/local/lib/python3.7/site-packages/django/db/utils.py", line 90, in __exit__
    raise dj_exc_value.with_traceback(traceback) from exc_value
  File "/usr/local/lib/python3.7/site-packages/django/db/backends/utils.py", line 84, in _execute
    return self.cursor.execute(sql, params)
  File "/usr/local/lib/python3.7/site-packages/django/db/backends/mysql/base.py", line 73, in execute
    return self.cursor.execute(query, args)
  File "/usr/local/lib/python3.7/site-packages/MySQLdb/cursors.py", line 206, in execute
    res = self._query(query)
  File "/usr/local/lib/python3.7/site-packages/MySQLdb/cursors.py", line 319, in _query
    db.query(q)
  File "/usr/local/lib/python3.7/site-packages/MySQLdb/connections.py", line 254, in query
    _mysql.connection.query(self, query)
django.db.utils.OperationalError: (1824, "Failed to open the referenced table 'accounts_user'")

python manage.py createsuperuser
Username: admin
Traceback (most recent call last):
  File "/usr/local/lib/python3.7/site-packages/django/db/backends/utils.py", line 84, in _execute
    return self.cursor.execute(sql, params)
  File "/usr/local/lib/python3.7/site-packages/django/db/backends/mysql/base.py", line 73, in execute
    return self.cursor.execute(query, args)
  File "/usr/local/lib/python3.7/site-packages/MySQLdb/cursors.py", line 206, in execute
    res = self._query(query)
  File "/usr/local/lib/python3.7/site-packages/MySQLdb/cursors.py", line 319, in _query
    db.query(q)
  File "/usr/local/lib/python3.7/site-packages/MySQLdb/connections.py", line 254, in query
    _mysql.connection.query(self, query)
MySQLdb._exceptions.ProgrammingError: (1146, "Table 'ldap.accounts_user' doesn't exist")

The above exception was the direct cause of the following exception:

Traceback (most recent call last):
  File "manage.py", line 22, in <module>
    main()
  File "manage.py", line 18, in main
    execute_from_command_line(sys.argv)
  File "/usr/local/lib/python3.7/site-packages/django/core/management/__init__.py", line 401, in execute_from_command_line
    utility.execute()
  File "/usr/local/lib/python3.7/site-packages/django/core/management/__init__.py", line 395, in execute
    self.fetch_command(subcommand).run_from_argv(self.argv)
  File "/usr/local/lib/python3.7/site-packages/django/core/management/base.py", line 330, in run_from_argv
    self.execute(*args, **cmd_options)
  File "/usr/local/lib/python3.7/site-packages/django/contrib/auth/management/commands/createsuperuser.py", line 79, in execute
    return super().execute(*args, **options)
  File "/usr/local/lib/python3.7/site-packages/django/core/management/base.py", line 371, in execute
    output = self.handle(*args, **options)
  File "/usr/local/lib/python3.7/site-packages/django/contrib/auth/management/commands/createsuperuser.py", line 113, in handle
    error_msg = self._validate_username(username, verbose_field_name, database)
  File "/usr/local/lib/python3.7/site-packages/django/contrib/auth/management/commands/createsuperuser.py", line 234, in _validate_username
    self.UserModel._default_manager.db_manager(database).get_by_natural_key(username)
  File "/usr/local/lib/python3.7/site-packages/django/contrib/auth/base_user.py", line 45, in get_by_natural_key
    return self.get(**{self.model.USERNAME_FIELD: username})
  File "/usr/local/lib/python3.7/site-packages/django/db/models/manager.py", line 85, in manager_method
    return getattr(self.get_queryset(), name)(*args, **kwargs)
  File "/usr/local/lib/python3.7/site-packages/django/db/models/query.py", line 425, in get
    num = len(clone)
  File "/usr/local/lib/python3.7/site-packages/django/db/models/query.py", line 269, in __len__
    self._fetch_all()
  File "/usr/local/lib/python3.7/site-packages/django/db/models/query.py", line 1303, in _fetch_all
    self._result_cache = list(self._iterable_class(self))
  File "/usr/local/lib/python3.7/site-packages/django/db/models/query.py", line 53, in __iter__
    results = compiler.execute_sql(chunked_fetch=self.chunked_fetch, chunk_size=self.chunk_size)
  File "/usr/local/lib/python3.7/site-packages/django/db/models/sql/compiler.py", line 1154, in execute_sql
    cursor.execute(sql, params)
  File "/usr/local/lib/python3.7/site-packages/django/db/backends/utils.py", line 98, in execute
    return super().execute(sql, params)
  File "/usr/local/lib/python3.7/site-packages/django/db/backends/utils.py", line 66, in execute
    return self._execute_with_wrappers(sql, params, many=False, executor=self._execute)
  File "/usr/local/lib/python3.7/site-packages/django/db/backends/utils.py", line 75, in _execute_with_wrappers
    return executor(sql, params, many, context)
  File "/usr/local/lib/python3.7/site-packages/django/db/backends/utils.py", line 84, in _execute
    return self.cursor.execute(sql, params)
  File "/usr/local/lib/python3.7/site-packages/django/db/utils.py", line 90, in __exit__
    raise dj_exc_value.with_traceback(traceback) from exc_value
  File "/usr/local/lib/python3.7/site-packages/django/db/backends/utils.py", line 84, in _execute
    return self.cursor.execute(sql, params)
  File "/usr/local/lib/python3.7/site-packages/django/db/backends/mysql/base.py", line 73, in execute
    return self.cursor.execute(query, args)
  File "/usr/local/lib/python3.7/site-packages/MySQLdb/cursors.py", line 206, in execute
    res = self._query(query)
  File "/usr/local/lib/python3.7/site-packages/MySQLdb/cursors.py", line 319, in _query
    db.query(q)
  File "/usr/local/lib/python3.7/site-packages/MySQLdb/connections.py", line 254, in query
    _mysql.connection.query(self, query)
django.db.utils.ProgrammingError: (1146, "Table 'ldap.accounts_user' doesn't exist")

DataError at /accounts/ldapserver/add/
(1406, "Data too long for column 'password' at row 1")
Request Method:	POST
Request URL:	http://49.232.6.131:8072/accounts/ldapserver/add/
Django Version:	3.1
Exception Type:	DataError
Exception Value:
(1406, "Data too long for column 'password' at row 1")
Exception Location:	/usr/local/lib/python3.7/site-packages/MySQLdb/connections.py, line 254, in query
Python Executable:	/usr/local/bin/python3
Python Version:	3.7.12
Python Path:
['/usr/local/lib/python3.7/site-packages/aliyunsdkcore',
 '/usr/local/lib/python3.7/site-packages/aliyunsdkcore',
 '/usr/local/lib/python3.7/site-packages/aliyunsdkcore',
 '/usr/local/lib/python3.7/site-packages/aliyunsdkcore',
 '/usr/local/lib/python3.7/site-packages',
 '/usr/local/lib/python3.7/site-packages/aliyunsdkcore',
 '/usr/local/lib/python3.7/site-packages/aliyunsdkcore',
 '/canary-platform',
 '/usr/local/lib/python37.zip',
 '/usr/local/lib/python3.7',
 '/usr/local/lib/python3.7/lib-dynload',
 '/usr/local/lib/python3.7/site-packages']
Server time:	Sun, 24 Apr 2022 17:54:33 +0800

show create table accounts_user\G
*************************** 1. row ***************************
       Table: accounts_user
Create Table: CREATE TABLE `accounts_user` (
  `id` int NOT NULL AUTO_INCREMENT,
  `password` varchar(128) COLLATE utf8mb4_unicode_ci NOT NULL,
  `last_login` datetime(6) DEFAULT NULL,
  `username` varchar(40) COLLATE utf8mb4_unicode_ci NOT NULL,
  `nickname` varchar(64) COLLATE utf8mb4_unicode_ci DEFAULT NULL,
  `email` varchar(255) COLLATE utf8mb4_unicode_ci DEFAULT NULL,
  `phone` varchar(64) COLLATE utf8mb4_unicode_ci DEFAULT NULL,
  `source` varchar(10) COLLATE utf8mb4_unicode_ci DEFAULT NULL,
  `is_lock` tinyint(1) NOT NULL,
  `is_active` tinyint(1) NOT NULL,
  `is_superuser` tinyint(1) NOT NULL,
  `is_staff` tinyint(1) NOT NULL,
  `unionid` varchar(64) COLLATE utf8mb4_unicode_ci DEFAULT NULL,
  PRIMARY KEY (`id`),
  UNIQUE KEY `username` (`username`)
) ENGINE=InnoDB AUTO_INCREMENT=2 DEFAULT CHARSET=utf8mb4 COLLATE=utf8mb4_unicode_ci
1 row in set (0.00 sec)

show create table accounts_ldapserver\G
*************************** 1. row ***************************
       Table: accounts_ldapserver
Create Table: CREATE TABLE `accounts_ldapserver` (
  `id` int NOT NULL AUTO_INCREMENT,
  `host` varchar(40) COLLATE utf8mb4_unicode_ci NOT NULL,
  `port` int NOT NULL,
  `user` varchar(100) COLLATE utf8mb4_unicode_ci NOT NULL,
  `password` varchar(100) COLLATE utf8mb4_unicode_ci NOT NULL,
  `use_ssl` tinyint(1) NOT NULL,
  `ldap_server` varchar(30) COLLATE utf8mb4_unicode_ci NOT NULL,
  `desc` varchar(64) COLLATE utf8mb4_unicode_ci DEFAULT NULL,
  `ldap_base_dn` varchar(100) COLLATE utf8mb4_unicode_ci DEFAULT NULL,
  `ldap_user_dn` varchar(50) COLLATE utf8mb4_unicode_ci DEFAULT NULL,
  `ldap_group_dn` varchar(50) COLLATE utf8mb4_unicode_ci DEFAULT NULL,
  `ldap_user_object_class` varchar(50) COLLATE utf8mb4_unicode_ci DEFAULT NULL,
  `ldap_group_object_class` varchar(50) COLLATE utf8mb4_unicode_ci DEFAULT NULL,
  PRIMARY KEY (`id`),
  UNIQUE KEY `host` (`host`)
) ENGINE=InnoDB DEFAULT CHARSET=utf8mb4 COLLATE=utf8mb4_unicode_ci
1 row in set (0.00 sec)